Workbook

Sheet Foglio1
A1: RISPOSTA SPETTRALE GIUNZIONE P-N
A3: λ (A) | B3: I (mA) | C3: err lam (A) | D3: I u. a. (A)
A4: 3745 | B4: 3e-05 | C4: 5 | D4: =B4*0.001/(13*0.000001) -> 0.0023076923
A5: =A4+98 -> 3843 | B5: 5e-05 | D5: =B5*0.001/(13*0.000001) -> 0.0038461538
A6: =A5+98 -> 3941 | B6: 8e-05 | D6: =B6*0.001/(13*0.000001) -> 0.0061538462
A7: =A6+98 -> 4039 | B7: 0.00013 | D7: =B7*0.001/(13*0.000001) -> 0.01
A8: =A7+98 -> 4137 | B8: 0.00018 | D8: =B8*0.001/(13*0.000001) -> 0.013846154
A9: =A8+98 -> 4235 | B9: 0.00025 | D9: =B9*0.001/(13*0.000001) -> 0.019230769
A10: =A9+98 -> 4333 | B10: 0.00033 | D10: =B10*0.001/(13*0.000001) -> 0.025384615
A11: =A10+98 -> 4431 | B11: 0.00044 | D11: =B11*0.001/(13*0.000001) -> 0.033846154
A12: =A11+98 -> 4529 | B12: 0.00055 | D12: =B12*0.001/(13*0.000001) -> 0.042307692
A13: =A12+98 -> 4627 | B13: 0.00067 | D13: =B13*0.001/(13*0.000001) -> 0.051538462
A14: =A13+98 -> 4725 | B14: 0.00075 | D14: =B14*0.001/(13*0.000001) -> 0.057692308
A15: =A14+98 -> 4823 | B15: 0.00091 | D15: =B15*0.001/(13*0.000001) -> 0.07
A16: =A15+98 -> 4921 | B16: 0.00103 | D16: =B16*0.001/(13*0.000001) -> 0.079230769
... A24: =A23+98 -> 5705 | B24: 0.00266 | D24: =B24*0.001/(13*0.000001) -> 0.20461538
A25: =A24+102 -> 5807 | B25: 0.00295 | D25: =B25*0.001/(13*0.000001) -> 0.22692308
A26: =A25+102 -> 5909 | B26: 0.0036 | D26: =B26*0.001/(13*0.000001) -> 0.27692308
A27: =A26+102 -> 6011 | B27: 0.00384 | D27: =B27*0.001/(13*0.000001) -> 0.29538462
A28: =A27+102 -> 6113 | B28: 0.00388 | D28: =B28*0.001/(13*0.000001) -> 0.29846154
A29: =A28+102 -> 6215 | B29: 0.00399 | D29: =B29*0.001/(13*0.000001) -> 0.30692308
A30: =A29+102 -> 6317 | B30: 0.00414 | D30: =B30*0.001/(13*0.000001) -> 0.31846154
A31: =A30+102 -> 6419 | B31: 0.00432 | D31: =B31*0.001/(13*0.000001) -> 0.33230769
A32: =A31+102 -> 6521 | B32: 0.004449 | D32: =B32*0.001/(13*0.000001) -> 0.34223077
A33: =A32+102 -> 6623 | B33: 0.00466 | D33: =B33*0.001/(13*0.000001) -> 0.35846154
A34: =A33+102 -> 6725 | B34: 0.00482 | D34: =B34*0.001/(13*0.000001) -> 0.37076923
A35: =A34+102 -> 6827 | B35: 0.00497 | D35: =B35*0.001/(13*0.000001) -> 0.38230769
A36: =A35+102 -> 6929 | B36: 0.0051 | D36: =B36*0.001/(13*0.000001) -> 0.39230769
... A57: =A56+102 -> 9071 | B57: 0.00811 | D57: =B57*0.001/(13*0.000001) -> 0.62384615
A58: =A57+51 -> 9122 | B58: 0.0083 | D58: =B58*0.001/(13*0.000001) -> 0.63846154
A59: =A58+51 -> 9173 | B59: 0.00865 | D59: =B59*0.001/(13*0.000001) -> 0.66538462
A60: =A59+51 -> 9224 | B60: 0.00892 | D60: =B60*0.001/(13*0.000001) -> 0.68615385
A61: =A60+51 -> 9275 | B61: 0.00915 | D61: =B61*0.001/(13*0.000001) -> 0.70384615
A62: =A61+51 -> 9326 | B62: 0.00937 | D62: =B62*0.001/(13*0.000001) -> 0.72076923
A63: =A62+51 -> 9377 | B63: 0.00953 | D63: =B63*0.001/(13*0.000001) -> 0.73307692
A64: =A63+51 -> 9428 | B64: 0.0097 | D64: =B64*0.001/(13*0.000001) -> 0.74615385
A65: =A64+51 -> 9479 | B65: 0.00987 | D65: =B65*0.001/(13*0.000001) -> 0.75923077
A66: =A65+51 -> 9530 | B66: 0.01 | D66: =B66*0.001/(13*0.000001) -> 0.76923077
A67: =A66+51 -> 9581 | B67: 0.01021 | D67: =B67*0.001/(13*0.000001) -> 0.78538462
A68: =A67+51 -> 9632 | B68: 0.01129 | D68: =B68*0.001/(13*0.000001) -> 0.86846154
...

Sheet Foglio2
A2: TERMOPILA | D2: =Foglio3!H3 -> 13
A3: λ | B3: V (mV) | C3: V (V) | D3: P | E3: err V | F3: p (mW) | G3: P u.a.
A4: 3745 | B4: 0.00037 | C4: =B4*0.001 -> 3.7e-07 | D4: =C4/$D$2 -> 2.8461538e-08 | E4: 0.0001 | F4: =D4*0.001 -> 0 | G4: =D4/(4*0.000001) -> 0.0071153846
A5: =A4+98 -> 3843 | B5: 0.0055 | C5: =B5*0.001 -> 5.5e-06 | D5: =C5/$D$2 -> 4.2307692e-07 | F5: =D5*0.001 -> 4.2307692e-10 | G5: =D5/(4*0.000001) -> 0.10576923
A6: =A5+98 -> 3941 | B6: 0.0075 | C6: =B6*0.001 -> 7.5e-06 | D6: =C6/$D$2 -> 5.7692308e-07 | F6: =D6*0.001 -> 5.7692308e-10 | G6: =D6/(4*0.000001) -> 0.14423077
A7: =A6+98 -> 4039 | B7: 0.01 | C7: =B7*0.001 -> 1e-05 | D7: =C7/$D$2 -> 7.6923077e-07 | F7: =D7*0.001 -> 7.6923077e-10 | G7: =D7/(4*0.000001) -> 0.19230769
A8: =A7+98 -> 4137 | B8: 0.0125 | C8: =B8*0.001 -> 1.25e-05 | D8: =C8/$D$2 -> 9.6153846e-07 | F8: =D8*0.001 -> 9.6153846e-10 | G8: =D8/(4*0.000001) -> 0.24038462
A9: =A8+98 -> 4235 | B9: 0.018 | C9: =B9*0.001 -> 1.8e-05 | D9: =C9/$D$2 -> 1.3846154e-06 | F9: =D9*0.001 -> 1.3846154e-09 | G9: =D9/(4*0.000001) -> 0.34615385
A10: =A9+98 -> 4333 | B10: 0.019 | C10: =B10*0.001 -> 1.9e-05 | D10: =C10/$D$2 -> 1.4615385e-06 | F10: =D10*0.001 -> 1.4615385e-09 | G10: =D10/(4*0.000001) -> 0.36538462
A11: =A10+98 -> 4431 | B11: 0.0215 | C11: =B11*0.001 -> 2.15e-05 | D11: =C11/$D$2 -> 1.6538462e-06 | F11: =D11*0.001 -> 1.6538462e-09 | G11: =D11/(4*0.000001) -> 0.41346154
A12: =A11+98 -> 4529 | B12: 0.0225 | C12: =B12*0.001 -> 2.25e-05 | D12: =C12/$D$2 -> 1.7307692e-06 | F12: =D12*0.001 -> 1.7307692e-09 | G12: =D12/(4*0.000001) -> 0.43269231
A13: =A12+98 -> 4627 | B13: 0.0255 | C13: =B13*0.001 -> 2.55e-05 | D13: =C13/$D$2 -> 1.9615385e-06 | F13: =D13*0.001 -> 1.9615385e-09 | G13: =D13/(4*0.000001) -> 0.49038462
A14: =A13+98 -> 4725 | B14: 0.027 | C14: =B14*0.001 -> 2.7e-05 | D14: =C14/$D$2 -> 2.0769231e-06 | F14: =D14*0.001 -> 2.0769231e-09 | G14: =D14/(4*0.000001) -> 0.51923077
A15: =A14+98 -> 4823 | B15: 0.0285 | C15: =B15*0.001 -> 2.85e-05 | D15: =C15/$D$2 -> 2.1923077e-06 | F15: =D15*0.001 -> 2.1923077e-09 | G15: =D15/(4*0.000001) -> 0.54807692
A16: =A15+98 -> 4921 | B16: 0.0315 | C16: =B16*0.001 -> 3.15e-05 | D16: =C16/$D$2 -> 2.4230769e-06 | F16: =D16*0.001 -> 2.4230769e-09 | G16: =D16/(4*0.000001) -> 0.60576923
... A24: =A23+98 -> 5705 | B24: 0.052 | C24: =B24*0.001 -> 5.2e-05 | D24: =C24/$D$2 -> 4e-06 | F24: =D24*0.001 -> 4e-09 | G24: =D24/(4*0.000001) -> 1
A25: =A24+102 -> 5807 | B25: 0.054 | C25: =B25*0.001 -> 5.4e-05 | D25: =C25/$D$2 -> 4.1538462e-06 | F25: =D25*0.001 -> 4.1538462e-09 | G25: =D25/(4*0.000001) -> 1.0384615
A26: =A25+102 -> 5909 | B26: 0.061 | C26: =B26*0.001 -> 6.1e-05 | D26: =C26/$D$2 -> 4.6923077e-06 | F26: =D26*0.001 -> 4.6923077e-09 | G26: =D26/(4*0.000001) -> 1.1730769
A27: =A26+102 -> 6011 | B27: 0.062 | C27: =B27*0.001 -> 6.2e-05 | D27: =C27/$D$2 -> 4.7692308e-06 | F27: =D27*0.001 -> 4.7692308e-09 | G27: =D27/(4*0.000001) -> 1.1923077
A28: =A27+102 -> 6113 | B28: 0.06 | C28: =B28*0.001 -> 6e-05 | D28: =C28/$D$2 -> 4.6153846e-06 | F28: =D28*0.001 -> 4.6153846e-09 | G28: =D28/(4*0.000001) -> 1.1538462
A29: =A28+102 -> 6215 | B29: 0.06 | C29: =B29*0.001 -> 6e-05 | D29: =C29/$D$2 -> 4.6153846e-06 | F29: =D29*0.001 -> 4.6153846e-09 | G29: =D29/(4*0.000001) -> 1.1538462
A30: =A29+102 -> 6317 | B30: 0.059 | C30: =B30*0.001 -> 5.9e-05 | D30: =C30/$D$2 -> 4.5384615e-06 | F30: =D30*0.001 -> 4.5384615e-09 | G30: =D30/(4*0.000001) -> 1.1346154
A31: =A30+102 -> 6419 | B31: 0.058 | C31: =B31*0.001 -> 5.8e-05 | D31: =C31/$D$2 -> 4.4615385e-06 | F31: =D31*0.001 -> 4.4615385e-09 | G31: =D31/(4*0.000001) -> 1.1153846
A32: =A31+102 -> 6521 | B32: 0.06 | C32: =B32*0.001 -> 6e-05 | D32: =C32/$D$2 -> 4.6153846e-06 | F32: =D32*0.001 -> 4.6153846e-09 | G32: =D32/(4*0.000001) -> 1.1538462
A33: =A32+102 -> 6623 | B33: 0.061 | C33: =B33*0.001 -> 6.1e-05 | D33: =C33/$D$2 -> 4.6923077e-06 | F33: =D33*0.001 -> 4.6923077e-09 | G33: =D33/(4*0.000001) -> 1.1730769
A34: =A33+102 -> 6725 | B34: 0.059 | C34: =B34*0.001 -> 5.9e-05 | D34: =C34/$D$2 -> 4.5384615e-06 | F34: =D34*0.001 -> 4.5384615e-09 | G34: =D34/(4*0.000001) -> 1.1346154
A35: =A34+102 -> 6827 | B35: 0.06 | C35: =B35*0.001 -> 6e-05 | D35: =C35/$D$2 -> 4.6153846e-06 | F35: =D35*0.001 -> 4.6153846e-09 | G35: =D35/(4*0.000001) -> 1.1538462
A36: =A35+102 -> 6929 | B36: 0.06 | C36: =B36*0.001 -> 6e-05 | D36: =C36/$D$2 -> 4.6153846e-06 | F36: =D36*0.001 -> 4.6153846e-09 | G36: =D36/(4*0.000001) -> 1.1538462
... A57: =A56+102 -> 9071 | B57: 0.0625 | C57: =B57*0.001 -> 6.25e-05 | D57: =C57/$D$2 -> 4.8076923e-06 | F57: =D57*0.001 -> 4.8076923e-09 | G57: =D57/(4*0.000001) -> 1.2019231
A58: =A57+51 -> 9122 | B58: 0.064 | C58: =B58*0.001 -> 6.4e-05 | D58: =C58/$D$2 -> 4.9230769e-06 | F58: =D58*0.001 -> 4.9230769e-09 | G58: =D58/(4*0.000001) -> 1.2307692
A59: =A58+51 -> 9173 | B59: 0.065 | C59: =B59*0.001 -> 6.5e-05 | D59: =C59/$D$2 -> 5e-06 | F59: =D59*0.001 -> 5e-09 | G59: =D59/(4*0.000001) -> 1.25
A60: =A59+51 -> 9224 | B60: 0.069 | C60: =B60*0.001 -> 6.9e-05 | D60: =C60/$D$2 -> 5.3076923e-06 | F60: =D60*0.001 -> 5.3076923e-09 | G60: =D60/(4*0.000001) -> 1.3269231
A61: =A60+51 -> 9275 | B61: 0.068 | C61: =B61*0.001 -> 6.8e-05 | D61: =C61/$D$2 -> 5.2307692e-06 | F61: =D61*0.001 -> 5.2307692e-09 | G61: =D61/(4*0.000001) -> 1.3076923
A62: =A61+51 -> 9326 | B62: 0.07 | C62: =B62*0.001 -> 7e-05 | D62: =C62/$D$2 -> 5.3846154e-06 | F62: =D62*0.001 -> 5.3846154e-09 | G62: =D62/(4*0.000001) -> 1.3461538
A63: =A62+51 -> 9377 | B63: 0.071 | C63: =B63*0.001 -> 7.1e-05 | D63: =C63/$D$2 -> 5.4615385e-06 | F63: =D63*0.001 -> 5.4615385e-09 | G63: =D63/(4*0.000001) -> 1.3653846
A64: =A63+51 -> 9428 | B64: 0.07 | C64: =B64*0.001 -> 7e-05 | D64: =C64/$D$2 -> 5.3846154e-06 | F64: =D64*0.001 -> 5.3846154e-09 | G64: =D64/(4*0.000001) -> 1.3461538
A65: =A64+51 -> 9479 | B65: 0.072 | C65: =B65*0.001 -> 7.2e-05 | D65: =C65/$D$2 -> 5.5384615e-06 | F65: =D65*0.001 -> 5.5384615e-09 | G65: =D65/(4*0.000001) -> 1.3846154
A66: =A65+51 -> 9530 | B66: 0.073 | C66: =B66*0.001 -> 7.3e-05 | D66: =C66/$D$2 -> 5.6153846e-06 | F66: =D66*0.001 -> 5.6153846e-09 | G66: =D66/(4*0.000001) -> 1.4038462
A67: =A66+51 -> 9581 | B67: 0.0735 | C67: =B67*0.001 -> 7.35e-05 | D67: =C67/$D$2 -> 5.6538462e-06 | F67: =D67*0.001 -> 5.6538462e-09 | G67: =D67/(4*0.000001) -> 1.4134615
A68: =A67+51 -> 9632 | B68: 0.081 | C68: =B68*0.001 -> 8.1e-05 | D68: =C68/$D$2 -> 6.2307692e-06 | F68: =D68*0.001 -> 6.2307692e-09 | G68: =D68/(4*0.000001) -> 1.5576923
...

Sheet Foglio3
A1: responsività
A2: λ | B2: I (A) | C2: P (W) | E2: Resp
H3: 13 | J3: =MAX(J4:J108) -> 0.56251969
A4: 3843 | B4: 0.0038461538 | C4: =Foglio2!G4 -> 0.0071153846 | E4: =B4/C4 -> 0.54054054 | G4: =Foglio1!A4 -> 3745 | H4: =Foglio1!D4 -> 0.0023076923 | I4: =Foglio2!G4 -> 0.0071153846 | J4: =H4/I4 -> 0.32432432
A5: 3941 | B5: 0.0061538462 | C5: 0.17045455 | E5: =B5/C5 -> 0.036102564 | G5: =Foglio1!A5 -> 3843 | H5: =Foglio1!D5 -> 0.0038461538 | I5: =Foglio2!G5 -> 0.10576923 | J5: =H5/I5 -> 0.036363636
A6: 4039 | B6: 0.01 | C6: 0.22727273 | E6: =B6/C6 -> 0.044 | G6: =Foglio1!A6 -> 3941 | H6: =Foglio1!D6 -> 0.0061538462 | I6: =Foglio2!G6 -> 0.14423077 | J6: =H6/I6 -> 0.042666667
A7: 4137 | B7: 0.013846154 | C7: 0.28409091 | E7: =B7/C7 -> 0.048738462 | G7: =Foglio1!A7 -> 4039 | H7: =Foglio1!D7 -> 0.01 | I7: =Foglio2!G7 -> 0.19230769 | J7: =H7/I7 -> 0.052
A8: 4235 | B8: 0.019230769 | C8: 0.40909091 | E8: =B8/C8 -> 0.047008547 | G8: =Foglio1!A8 -> 4137 | H8: =Foglio1!D8 -> 0.013846154 | I8: =Foglio2!G8 -> 0.24038462 | J8: =H8/I8 -> 0.0576
A9: 4333 | B9: 0.025384615 | C9: 0.43181818 | E9: =B9/C9 -> 0.058785425 | G9: =Foglio1!A9 -> 4235 | H9: =Foglio1!D9 -> 0.019230769 | I9: =Foglio2!G9 -> 0.34615385 | J9: =H9/I9 -> 0.055555556
A10: 4431 | B10: 0.033846154 | C10: 0.48863636 | E10: =B10/C10 -> 0.069266547 | G10: =Foglio1!A10 -> 4333 | H10: =Foglio1!D10 -> 0.025384615 | I10: =Foglio2!G10 -> 0.36538462 | J10: =H10/I10 -> 0.069473684
A11: 4529 | B11: 0.042307692 | C11: 0.51136364 | E11: =B11/C11 -> 0.082735043 | G11: =Foglio1!A11 -> 4431 | H11: =Foglio1!D11 -> 0.033846154 | I11: =Foglio2!G11 -> 0.41346154 | J11: =H11/I11 -> 0.081860465
A12: 4627 | B12: 0.051538462 | C12: 0.57954545 | E12: =B12/C12 -> 0.08892911 | G12: =Foglio1!A12 -> 4529 | H12: =Foglio1!D12 -> 0.042307692 | I12: =Foglio2!G12 -> 0.43269231 | J12: =H12/I12 -> 0.097777778
A13: 4725 | B13: 0.057692308 | C13: 0.61363636 | E13: =B13/C13 -> 0.094017094 | G13: =Foglio1!A13 -> 4627 | H13: =Foglio1!D13 -> 0.051538462 | I13: =Foglio2!G13 -> 0.49038462 | J13: =H13/I13 -> 0.10509804
A14: 4823 | B14: 0.07 | C14: 0.64772727 | E14: =B14/C14 -> 0.10807018 | G14: =Foglio1!A14 -> 4725 | H14: =Foglio1!D14 -> 0.057692308 | I14: =Foglio2!G14 -> 0.51923077 | J14: =H14/I14 -> 0.11111111
A15: 4921 | B15: 0.079230769 | C15: 0.71590909 | E15: =B15/C15 -> 0.11067155 | G15: =Foglio1!A15 -> 4823 | H15: =Foglio1!D15 -> 0.07 | I15: =Foglio2!G15 -> 0.54807692 | J15: =H15/I15 -> 0.1277193
A16: 5019 | B16: 0.090769231 | C16: 0.75 | E16: =B16/C16 -> 0.12102564 | G16: =Foglio1!A16 -> 4921 | H16: =Foglio1!D16 -> 0.079230769 | I16: =Foglio2!G16 -> 0.60576923 | J16: =H16/I16 -> 0.13079365
... A108: 11723 | B108: 0.0023076923 | C108: 1.5909091 | E108: =B108/C108 -> 0.0014505495 | G108: =Foglio1!A108 -> 11672 | H108: =Foglio1!D108 -> 0.0053846154 | I108: =Foglio2!G108 -> 1.3461538 | J108: =H108/I108 -> 0.004
